Workbook

Sheet Read Me
B7: RIDGELINE CONSTRUCTION — Project Template
B9: TABS
B10: Settings · Specifications (descriptions) · Estimate (pricing) · Schedule.
B16: PRICING (cost ▸ markup ▸ ext ▸ tax ▸ total)
B17: Enter My Cost & Markup % in the yellow INTERNAL columns (right). Ext Cost = cost + markup = the
B18: customer's pre-tax price. Those internal columns are outside the print area — never printed.
B20: DESCRIPTIONS & PRINTING
B21: Click a blue cost code to jump to its description on Specifications. Run PrintPacket (Alt+F8) for the
B22: clean packet: Specifications ▸ Estimate ▸ (optional) Schedule.
B24: MACROS (import Ridgeline_Macros.bas: Alt+F11 ▸ File ▸ Import)
B25: AddCostLine · DeleteCostLine · AdoptSuggested · BuildScheduleFromToggles · PrintPacket · ExportScheduleICS · PublishProject.
B27: Prefer no macros? Ask me to publish or export a calendar and I'll do it here.
... B38: Import = the .bas (buttons). Paste into the Schedule sheet = the .txt (auto status behavior).

Sheet Settings
C2: RIDGELINE CONSTRUCTION
C3: Estimate + Schedule - master project template
B7: Project Information
B8: Project / Client | C8: Truesdell SFD
B9: Project Address
B10: Estimate # | C10: EST-1001
B12: Takeoff Quantities (drive the Suggested $ column)
B13: Living space SF | C13: 1800 | D13: Heated area; drives $/sf, flooring, framing, etc.
B14: Garage SF | C14: 400
B15: Covered porch SF | C15: 120
B16: Deck SF | C16: 0
B17: Covered deck SF | C17: 0
B18: Exterior concrete SF | C18: 600
B19: Driveway length (lf) | C19: 40
B20: Foundation wall (lin ft) | C20: 190
B21: Avg foundation wall ht (ft) | C21: 4
B22: Avg ceiling ht (ft) | C22: 9
B23: Exterior wall SF | C23: =C20*C22 -> 1710 | D23: foundation lf x avg ceiling ht
B24: Tile area SF | C24: 400
B25: Remaining floor SF | C25: =MAX(C13-C24,0) -> 1400 | D25: living minus tile (to LVT/laminate)
B26: Kitchen run (lin ft) | C26: 20 | D26: Counter + upper & lower cab length
B27: Windows (qty) | C27: 18
B28: Exterior doors (qty) | C28: 3
B29: Sliding glass doors (qty) | C29: 1
B30: Garage doors (qty) | C30: 1
B31: Total under roof | C31: =C13+C14+C15 -> 2320 | D31: Living + garage + covered porch
B32: Gable area SF | C32: 0 | D32: Added to siding labor/paint & material totals
B33: Assumptions
B34: Sales Tax % | C34: 0.079 | D34: Shown to customer; applied to taxable lines
B35: Default Markup % | C35: 0.2 | D35: INTERNAL margin - drives every non-passthrough line
B36: Project Start Date | C36: 46204 | D36: Schedule + milestones flow from this
B38: Company / Branding
B39: Company | C39: Ridgeline Construction
B40: Mailing | C40: PO Box 516, Longview, WA 98632
B41: Phone | C41: 360-200-1716
B43: Milestone Anchor Dates (auto from start; edit as needed)
B44: Financing | C44: =$C$36 -> 46204
B45: Permitting | C45: =EDATE($C$36,1) -> 46235
B46: Foundation | C46: =EDATE($C$36,2) -> 46266

Sheet Specifications
B1: SPECIFICATIONS
B2: =Settings!C40&" • "&Settings!C41 -> PO Box 516, Longview, WA 98632 • 360-200-1716
B3: ="Project: "&Settings!C8&" Estimate "&Settings!C10 -> Project: Truesdell SFD Estimate EST-1001
A5: Code | B5: Item & Specification
A6: 0100 | B6: General Conditions
A7: 0110 | B7: Permits (Allowance)
B8: Builder will prepare and submit applications for the standard building, mechanical, plumbing, and electrical permits required by the jurisdiction. The permit allowance covers typical permit fees and is billed at actual cost. Not included: planning/design review, SEPA or environmental review, impact, traffic, school, or park fees, and any plan-revision fees — these are billed in addition if required. Owner is responsible for HOA submittals and approvals.
A9: 0120 | B9: Electrical Utility Connections (Allowance)
B10: Electric: connection to public power including transformer and meter base. Service is assumed available at the road adjacent to the property line; trenching, conduit, or boring beyond that point is not included. Gas (if applicable): coordination of the gas service connection to the meter — confirm provider and tap location. Cable / phone / internet: owner coordinates underground installation with Comcast & CenturyLink and arranges activation after taking possession.
A11: 0130 | B11: Excavation (Allowance)
B12: Strip and stockpile existing topsoil on site where practical. Excavate for the foundation to plan bottom per the architectural drawings; spoils are stockpiled for backfill. Unknowns: unsuitable or unstable soils (rock, soft clay, sinkholes, high water table) cannot be priced before excavation and are billed as a change if encountered. Builder backfills with existing soils, rough-grades excess on site, and spreads stockpiled topsoil over disturbed areas. Owner is responsible for seeding, irrigation, fertilizing, and final yard. Not included: import of additional topsoil, off-site haul of excess spoils (except demolition debris), hidden/undisclosed wells, tanks, or pits. Erosion control (silt fence) installed and maintained per permit.
A13: 0140 | B13: Septic system design & install (Allowance)
B14: Design, permitting, and installation of an on-site septic system, assumed to be a pressure-distribution system without pretreatment. Includes tank, pump, drainfield, control panel, and float alarm. Final engineered design and health-department approval are required to confirm system type, size, and cost; pretreatment (if required by the site/soils) is an added cost.
A15: 0150 | B15: Well setup (Allowance)
B16: Well pump, pressure tank, controller/pressure switch, and wiring from the panel to the well. Not included unless noted: well drilling, well house/pump house, and water treatment — coordinate with the well driller. *(Currently $0 — confirm whether the lot is on a well or public water.)*
A17: 0190 | B17: Job site services
B18: General conditions for the duration of the project: temporary toilet maintained on site, dumpsters/debris removal as needed, and ongoing site cleanup. Professional rough and final cleaning, with a detailed final clean before the owner orientation/walkthrough. Temporary power and water as needed during construction.
A19: 0200 | B19: Site Work
A20: 0210 | B20: Footing And Foundation
B21: Form and pour concrete footings and foundation walls per the structural drawings and IRC, including rebar, anchor bolts, and hold-downs. Includes footing/perimeter drain, damp-proofing of below-grade walls, and under-slab vapor barrier where slabs occur. Pricing is based on the current drawings; additional steps, taller walls, or engineered changes are billed as a change.
A22: 0300 | B22: Rough Structure
A23: 0310 | B23: Framing Materials (Allowance)
B24: All lumber and framing materials sized and spaced per the approved construction drawings; lumber to be #2 or better, kiln-dried. Floor sheathing 1‑1/8″ Edge Gold T&G OSB; wall and roof sheathing 7/16″ OSB with H-clips where applicable. Floor framing engineered I-joist or per plan; roof trusses/rafters per plan with vaults as drawn. Includes structural connectors, hangers, hold-downs, and fasteners.
A25: 0320 | B25: Framing Labor
B26: Construct the rough structure per the plans and engineering: floor system, walls, roof structure, and wall/roof sheathing. Includes setting exterior doors and windows, installing structural hardware, and providing solid backing for cabinets, railings, and bath fixtures. Includes shear-nail and framing inspections.
A27: 0400 | B27: Windows & Doors, Exterior
A28: 0410 | B28: Front Door (Allowance)
B29: Entry door per the drawings — allowance covers the door slab/unit, jamb, weatherstripping, and exterior hardware/lockset. Sample: 3/0 × 8/0 knotty alder. Decorative glass or custom sizes may affect the allowance.
A30: 0420 | B30: Other exterior doors
B31: Remaining exterior doors per plan (e.g., man-doors, patio/utility), including jambs, weatherstripping, and hardware. Sliding/French patio doors are itemized under Windows.
A32: 0430 | B32: Garage Doors
B33: Garage door(s) sized and quantity per plan. Spec: Clopay Bridgeport, steel, 2-layer insulated (R-6.3), white — e.g., 18′×8′. Includes track, springs, weather seal, and opener(s) with two remotes and exterior keypad (confirm opener count = door count).
A34: 0440 | B34: Windows (Allowance)
B35: Windows per plan — Milgard vinyl, white standard (other colors available at added cost). Includes Low-E / argon insulated glass, screens, and tempered glass where required by code (near doors, in wet areas, large/low units). Includes sliding glass door(s) per plan. Egress windows sized per code at sleeping rooms.
A36: 0500 | B36: Exterior Finishes
A37: 0510 | B37: Siding Materials
B38: Fiber-cement lap siding (Hardie), 7″ reveal; finger-joint primed cypress trim at corners and windows; primed cypress fascia/barge; cedar tongue-and-groove porch ceilings; LP soffits. Includes weather-resistive barrier (house wrap) and flashing/trim accessories.
A39: 0520 | B39: Siding Labor
B40: Install the weather-resistive barrier, window/door flashing, exterior trim, siding, soffits, and post wraps per the drawings, including all caulking and sealing.
A41: 0530 | B41: Roofing Specifications (Allowance)
...

Sheet Estimate
D1: ESTIMATE
D2: =Settings!C40&" • "&Settings!C41 -> PO Box 516, Longview, WA 98632 • 360-200-1716
D3: ="Project: "&Settings!C8&" Estimate "&Settings!C10 -> Project: Truesdell SFD Estimate EST-1001
H4: INTERNAL — not printed
A5: Code | B5: Item / Description | C5: Ext Cost | D5: Sales Tax | E5: Line Total | F5: Category / Item Total | H5: My Cost | I5: Markup | J5: Tax? | K5: Allow? | L5: Excl? | M5: Suggested $ | N5: Logic / basis | O5: Sched?
A6: 0100 | B6: General Conditions | F6: =F7+F9+F12+F17+F21+F23 -> 0
A7: 0110 | B7: ="Permits"&IF($K7="Y"," (Allowance)","") -> Permits (Allowance) | F7: =SUM(E8) -> 0 | K7: Y | O7: Y
B8: Bldg. Permit | C8: =IF($L8="Y",0,H8*(1+I8)) -> 0 | D8: =IF(J8="Y",C8*Settings!$C$34,0) -> 0 | E8: =C8+D8 -> 0 | H8: 0 | I8: 0 | J8: N | L8: N | M8: 8000 | N8: Prior project basis / lump sum - confirm with sub
A9: 0120 | B9: ="Electrical Utility Connections"&IF($K9="Y"," (Allowance)","") -> Electrical Utility Connections (Allowance) | F9: =SUM(E10:E11) -> 0 | K9: Y | O9: Y
B10: PUD Quoted install | C10: =IF($L10="Y",0,H10*(1+I10)) -> 0 | D10: =IF(J10="Y",C10*Settings!$C$34,0) -> 0 | E10: =C10+D10 -> 0 | H10: 0 | I10: 0 | J10: N | L10: N | M10: 7500 | N10: Prior project basis / lump sum - confirm with sub
B11: Gas service connection | C11: =IF($L11="Y",0,H11*(1+I11)) -> 0 | D11: =IF(J11="Y",C11*Settings!$C$34,0) -> 0 | E11: =C11+D11 -> 0 | H11: 0 | I11: 0 | J11: N | L11: N | M11: =2500 -> 2500 | N11: Allowance - gas tap/meter; confirm provider
A12: 0130 | B12: ="Excavation"&IF($K12="Y"," (Allowance)","") -> Excavation (Allowance) | F12: =SUM(E13:E16) -> 0 | K12: Y | O12: Y
B13: Excavation | C13: =IF($L13="Y",0,H13*(1+I13)) -> 0 | D13: =IF(J13="Y",C13*Settings!$C$34,0) -> 0 | E13: =C13+D13 -> 0 | H13: 0 | I13: =Settings!$C$35 -> 0.2 | J13: Y | L13: N | M13: 4095 | N13: Prior project basis / lump sum - confirm with sub
B14: Excavation - utilities & contingency | C14: =IF($L14="Y",0,H14*(1+I14)) -> 0 | D14: =IF(J14="Y",C14*Settings!$C$34,0) -> 0 | E14: =C14+D14 -> 0 | H14: 0 | I14: =Settings!$C$35 -> 0.2 | J14: Y | L14: N | M14: 3510 | N14: Prior project basis / lump sum - confirm with sub
B15: Backfill - Labor | C15: =IF($L15="Y",0,H15*(1+I15)) -> 0 | D15: =IF(J15="Y",C15*Settings!$C$34,0) -> 0 | E15: =C15+D15 -> 0 | H15: 0 | I15: =Settings!$C$35 -> 0.2 | J15: Y | L15: N | M15: 5850 | N15: Prior project basis / lump sum - confirm with sub
B16: Backfill - Gravel and fill | C16: =IF($L16="Y",0,H16*(1+I16)) -> 0 | D16: =IF(J16="Y",C16*Settings!$C$34,0) -> 0 | E16: =C16+D16 -> 0 | H16: 0 | I16: =Settings!$C$35 -> 0.2 | J16: Y | L16: N | M16: 5850 | N16: Prior project basis / lump sum - confirm with sub
A17: 0140 | B17: ="Septic system design & install"&IF($K17="Y"," (Allowance)","") -> Septic system design & install (Allowance) | F17: =SUM(E18:E20) -> 0 | K17: Y | O17: Y
B18: Septic system install - Pressure distribution | C18: =IF($L18="Y",0,H18*(1+I18)) -> 0 | D18: =IF(J18="Y",C18*Settings!$C$34,0) -> 0 | E18: =C18+D18 -> 0 | H18: 0 | I18: =Settings!$C$35 -> 0.2 | J18: Y | L18: N | M18: 14040 | N18: Prior project basis / lump sum - confirm with sub
B19: Septic design | C19: =IF($L19="Y",0,H19*(1+I19)) -> 0 | D19: =IF(J19="Y",C19*Settings!$C$34,0) -> 0 | E19: =C19+D19 -> 0 | H19: 0 | I19: =Settings!$C$35 -> 0.2 | J19: Y | L19: N | M19: 1404 | N19: Prior project basis / lump sum - confirm with sub
B20: Septic permit | C20: =IF($L20="Y",0,H20*(1+I20)) -> 0 | D20: =IF(J20="Y",C20*Settings!$C$34,0) -> 0 | E20: =C20+D20 -> 0 | H20: 0 | I20: =Settings!$C$35 -> 0.2 | J20: Y | L20: N | M20: 1170 | N20: Prior project basis / lump sum - confirm with sub
A21: 0150 | B21: ="Well setup"&IF($K21="Y"," (Allowance)","") -> Well setup (Allowance) | F21: =SUM(E22) -> 0 | K21: Y | O21: N
B22: Well | C22: =IF($L22="Y",0,H22*(1+I22)) -> 0 | D22: =IF(J22="Y",C22*Settings!$C$34,0) -> 0 | E22: =C22+D22 -> 0 | H22: 0 | I22: 0 | J22: Y | L22: N | M22: 0 | N22: Owner-provided / allowance - set as needed
A23: 0190 | B23: ="Job site services"&IF($K23="Y"," (Allowance)","") -> Job site services | F23: =SUM(E24:E26) -> 0 | K23: N | O23: N
B24: Home Cleaning @ Final | C24: =IF($L24="Y",0,H24*(1+I24)) -> 0 | D24: =IF(J24="Y",C24*Settings!$C$34,0) -> 0 | E24: =C24+D24 -> 0 | H24: 0 | I24: =Settings!$C$35 -> 0.2 | J24: Y | L24: N | M24: 2925 | N24: Prior project basis / lump sum - confirm with sub
B25: Portable toilet | C25: =IF($L25="Y",0,H25*(1+I25)) -> 0 | D25: =IF(J25="Y",C25*Settings!$C$34,0) -> 0 | E25: =C25+D25 -> 0 | H25: 0 | I25: =Settings!$C$35 -> 0.2 | J25: Y | L25: N | M25: 1895.4 | N25: Prior project basis / lump sum - confirm with sub
B26: Dumping fees / site cleanup | C26: =IF($L26="Y",0,H26*(1+I26)) -> 0 | D26: =IF(J26="Y",C26*Settings!$C$34,0) -> 0 | E26: =C26+D26 -> 0 | H26: 0 | I26: =Settings!$C$35 -> 0.2 | J26: Y | L26: N | M26: 5850 | N26: Prior project basis / lump sum - confirm with sub
A27: 0200 | B27: Site Work | F27: =F28 -> 0
A28: 0210 | B28: ="Footing And Foundation"&IF($K28="Y"," (Allowance)","") -> Footing And Foundation | F28: =SUM(E29:E30) -> 0 | K28: N | O28: Y
B29: Foundation Labor/concrete | C29: =IF($L29="Y",0,H29*(1+I29)) -> 0 | D29: =IF(J29="Y",C29*Settings!$C$34,0) -> 0 | E29: =C29+D29 -> 0 | H29: 0 | I29: =Settings!$C$35 -> 0.2 | J29: Y | L29: N | M29: =CEILING(Settings!$C$20*Settings!$C$21*0.667/27,5)*440 -> 8800 | N29: Foundation CY (perim x ht x 0.67 /27, round up 5 yd) x $440/yd
B30: Pump Truck | C30: =IF($L30="Y",0,H30*(1+I30)) -> 0 | D30: =IF(J30="Y",C30*Settings!$C$34,0) -> 0 | E30: =C30+D30 -> 0 | H30: 0 | I30: =Settings!$C$35 -> 0.2 | J30: Y | L30: N | M30: 1872 | N30: Prior project basis / lump sum - confirm with sub
A31: 0300 | B31: Rough Structure | F31: =F32+F38 -> 0
A32: 0310 | B32: ="Framing Materials"&IF($K32="Y"," (Allowance)","") -> Framing Materials (Allowance) | F32: =SUM(E33:E37) -> 0 | K32: Y | O32: Y
B33: Materials - 1st floor - 9.5" TJI | C33: =IF($L33="Y",0,H33*(1+I33)) -> 0 | D33: =IF(J33="Y",C33*Settings!$C$34,0) -> 0 | E33: =C33+D33 -> 0 | H33: 0 | I33: =Settings!$C$35 -> 0.2 | J33: Y | L33: N | M33: ='Material Estimate'!$H$19 -> 9200.8976 | N33: From Material Takeoff: foundation & floor framing material
B34: Exterior Walls 9' PLT HT | C34: =IF($L34="Y",0,H34*(1+I34)) -> 0 | D34: =IF(J34="Y",C34*Settings!$C$34,0) -> 0 | E34: =C34+D34 -> 0 | H34: 0 | I34: =Settings!$C$35 -> 0.2 | J34: Y | L34: N | M34: ='Material Estimate'!$H$29 -> 3705.6653 | N34: From Material Takeoff: wall framing material
B35: Materials - Roof pack | C35: =IF($L35="Y",0,H35*(1+I35)) -> 0 | D35: =IF(J35="Y",C35*Settings!$C$34,0) -> 0 | E35: =C35+D35 -> 0 | H35: 0 | I35: =Settings!$C$35 -> 0.2 | J35: Y | L35: N | M35: ='Material Estimate'!$H$40 -> 4054.0079 | N35: From Material Takeoff: roof framing & trim material
B36: Materials - Trusses | C36: =IF($L36="Y",0,H36*(1+I36)) -> 0 | D36: =IF(J36="Y",C36*Settings!$C$34,0) -> 0 | E36: =C36+D36 -> 0 | H36: 0 | I36: =Settings!$C$35 -> 0.2 | J36: Y | L36: N | M36: 7020 | N36: Prior project basis / lump sum - confirm with sub
B37: Beams - hardware - Posts | C37: =IF($L37="Y",0,H37*(1+I37)) -> 0 | D37: =IF(J37="Y",C37*Settings!$C$34,0) -> 0 | E37: =C37+D37 -> 0 | H37: 0 | I37: =Settings!$C$35 -> 0.2 | J37: Y | L37: N | M37: 1404 | N37: Prior project basis / lump sum - confirm with sub
A38: 0320 | B38: ="Framing Labor"&IF($K38="Y"," (Allowance)","") -> Framing Labor | F38: =SUM(E39:E40) -> 0 | K38: N | O38: Y
B39: Framing labor - living space | C39: =IF($L39="Y",0,H39*(1+I39)) -> 0 | D39: =IF(J39="Y",C39*Settings!$C$34,0) -> 0 | E39: =C39+D39 -> 0 | H39: 0 | I39: =Settings!$C$35 -> 0.2 | J39: Y | L39: N | M39: =Settings!$C$13*12 -> 21600 | N39: Living SF x $12/sf framing labor
B40: Framing labor - Covered porch/Garage | C40: =IF($L40="Y",0,H40*(1+I40)) -> 0 | D40: =IF(J40="Y",C40*Settings!$C$34,0) -> 0 | E40: =C40+D40 -> 0 | H40: 0 | I40: =Settings!$C$35 -> 0.2 | J40: Y | L40: N | M40: =(Settings!$C$14+Settings!$C$15)*9 -> 4680 | N40: (Garage+porch) SF x $9/sf framing labor
...

Sheet Allowances
D1: ALLOWANCES
D2: =Settings!C40&" • "&Settings!C41 -> PO Box 516, Longview, WA 98632 • 360-200-1716
D3: ="Project: "&Settings!C8&" Estimate "&Settings!C10 -> Project: Truesdell SFD Estimate EST-1001
A4: Items toggled Allow? = Y on the Estimate. Enter the actual selected cost to track budget vs. spend.
A5: Code | B5: Category | C5: Item | D5: Allow? | E5: Allowance $ | F5: Actual $ | G5: Variance | H5: Notes
A6: =Estimate!A7 -> 0110 | B6: General Conditions | C6: Permits | D6: =Estimate!K7 -> Y | E6: =Estimate!F7 -> 0 | G6: =IF(F6="","",E6-F6)
A7: =Estimate!A9 -> 0120 | B7: General Conditions | C7: Electrical Utility Connections | D7: =Estimate!K9 -> Y | E7: =Estimate!F9 -> 0 | G7: =IF(F7="","",E7-F7)
A8: =Estimate!A12 -> 0130 | B8: General Conditions | C8: Excavation | D8: =Estimate!K12 -> Y | E8: =Estimate!F12 -> 0 | G8: =IF(F8="","",E8-F8)
A9: =Estimate!A17 -> 0140 | B9: General Conditions | C9: Septic system design & install | D9: =Estimate!K17 -> Y | E9: =Estimate!F17 -> 0 | G9: =IF(F9="","",E9-F9)
A10: =Estimate!A21 -> 0150 | B10: General Conditions | C10: Well setup | D10: =Estimate!K21 -> Y | E10: =Estimate!F21 -> 0 | G10: =IF(F10="","",E10-F10)
A11: =Estimate!A23 -> 0190 | B11: General Conditions | C11: Job site services | D11: =Estimate!K23 -> N | E11: =Estimate!F23 -> 0 | G11: =IF(F11="","",E11-F11)
A12: =Estimate!A28 -> 0210 | B12: Site Work | C12: Footing And Foundation | D12: =Estimate!K28 -> N | E12: =Estimate!F28 -> 0 | G12: =IF(F12="","",E12-F12)
A13: =Estimate!A32 -> 0310 | B13: Rough Structure | C13: Framing Materials | D13: =Estimate!K32 -> Y | E13: =Estimate!F32 -> 0 | G13: =IF(F13="","",E13-F13)
A14: =Estimate!A38 -> 0320 | B14: Rough Structure | C14: Framing Labor | D14: =Estimate!K38 -> N | E14: =Estimate!F38 -> 0 | G14: =IF(F14="","",E14-F14)
A15: =Estimate!A42 -> 0410 | B15: Windows & Doors, Exterior | C15: Front Door | D15: =Estimate!K42 -> Y | E15: =Estimate!F42 -> 0 | G15: =IF(F15="","",E15-F15)
A16: =Estimate!A44 -> 0420 | B16: Windows & Doors, Exterior | C16: Other exterior doors | D16: =Estimate!K44 -> N | E16: =Estimate!F44 -> 0 | G16: =IF(F16="","",E16-F16)
A17: =Estimate!A46 -> 0430 | B17: Windows & Doors, Exterior | C17: Garage Doors | D17: =Estimate!K46 -> N | E17: =Estimate!F46 -> 0 | G17: =IF(F17="","",E17-F17)
A18: =Estimate!A49 -> 0440 | B18: Windows & Doors, Exterior | C18: Windows | D18: =Estimate!K49 -> Y | E18: =Estimate!F49 -> 0 | G18: =IF(F18="","",E18-F18)
A19: =Estimate!A53 -> 0510 | B19: Exterior Finishes | C19: Siding Materials | D19: =Estimate!K53 -> N | E19: =Estimate!F53 -> 0 | G19: =IF(F19="","",E19-F19)
A20: =Estimate!A55 -> 0520 | B20: Exterior Finishes | C20: Siding Labor | D20: =Estimate!K55 -> N | E20: =Estimate!F55 -> 0 | G20: =IF(F20="","",E20-F20)
A21: =Estimate!A59 -> 0530 | B21: Exterior Finishes | C21: Roofing Specifications | D21: =Estimate!K59 -> Y | E21: =Estimate!F59 -> 0 | G21: =IF(F21="","",E21-F21)
A22: =Estimate!A62 -> 0540 | B22: Exterior Finishes | C22: Gutters | D22: =Estimate!K62 -> N | E22: =Estimate!F62 -> 0 | G22: =IF(F22="","",E22-F22)
A23: =Estimate!A64 -> 0550 | B23: Exterior Finishes | C23: Exterior Masonry | D23: =Estimate!K64 -> N | E23: =Estimate!F64 -> 0 | G23: =IF(F23="","",E23-F23)
A24: =Estimate!A66 -> 0560 | B24: Exterior Finishes | C24: Exterior Painting | D24: =Estimate!K66 -> N | E24: =Estimate!F66 -> 0 | G24: =IF(F24="","",E24-F24)
A25: =Estimate!A68 -> 0570 | B25: Exterior Finishes | C25: Concrete Flatwork | D25: =Estimate!K68 -> Y | E25: =Estimate!F68 -> 0 | G25: =IF(F25="","",E25-F25)
A26: =Estimate!A73 -> 0610 | B26: HVAC | C26: HVAC | D26: =Estimate!K73 -> N | E26: =Estimate!F73 -> 0 | G26: =IF(F26="","",E26-F26)
A27: =Estimate!A75 -> 0620 | B27: HVAC | C27: Fireplace | D27: =Estimate!K75 -> Y | E27: =Estimate!F75 -> 0 | G27: =IF(F27="","",E27-F27)
A28: =Estimate!A78 -> 0710 | B28: Plumbing | C28: Plumbing | D28: =Estimate!K78 -> Y | E28: =Estimate!F78 -> 0 | G28: =IF(F28="","",E28-F28)
A29: =Estimate!A81 -> 0810 | B29: Electrical | C29: Electrical | D29: =Estimate!K81 -> Y | E29: =Estimate!F81 -> 0 | G29: =IF(F29="","",E29-F29)
A30: =Estimate!A85 -> 0820 | B30: Electrical | C30: Electrical Fixtures | D30: =Estimate!K85 -> Y | E30: =Estimate!F85 -> 0 | G30: =IF(F30="","",E30-F30)
A31: =Estimate!A88 -> 0910 | B31: Insulation | C31: Insulation | D31: =Estimate!K88 -> N | E31: =Estimate!F88 -> 0 | G31: =IF(F31="","",E31-F31)
A32: =Estimate!A91 -> 1010 | B32: Interior Wall & Ceiling Finishes | C32: Drywall | D32: =Estimate!K91 -> N | E32: =Estimate!F91 -> 0 | G32: =IF(F32="","",E32-F32)
A33: =Estimate!A93 -> 1020 | B33: Interior Wall & Ceiling Finishes | C33: Interior Paint | D33: =Estimate!K93 -> N | E33: =Estimate!F93 -> 0 | G33: =IF(F33="","",E33-F33)
A34: =Estimate!A95 -> 1030 | B34: Interior Wall & Ceiling Finishes | C34: Interior Paint Color(s) | D34: =Estimate!K95 -> N | E34: =Estimate!F95 -> 0 | G34: =IF(F34="","",E34-F34)
A35: =Estimate!A96 -> 1040 | B35: Interior Wall & Ceiling Finishes | C35: Bathroom accessories and mirrors | D35: =Estimate!K96 -> Y | E35: =Estimate!F96 -> 0 | G35: =IF(F35="","",E35-F35)
A36: =Estimate!A99 -> 1050 | B36: Interior Wall & Ceiling Finishes | C36: Masonry - Fireplace facade | D36: =Estimate!K99 -> Y | E36: =Estimate!F99 -> 0 | G36: =IF(F36="","",E36-F36)
A37: =Estimate!A103 -> 1110 | B37: Flooring | C37: Flooring Labor | D37: =Estimate!K103 -> Y | E37: =Estimate!F103 -> 0 | G37: =IF(F37="","",E37-F37)
A38: =Estimate!A108 -> 1120 | B38: Flooring | C38: Flooring material | D38: =Estimate!K108 -> Y | E38: =Estimate!F108 -> 0 | G38: =IF(F38="","",E38-F38)
A39: =Estimate!A112 -> 1210 | B39: Woodwork/Cabinets/Millwork | C39: Millwork | D39: =Estimate!K112 -> N | E39: =Estimate!F112 -> 0 | G39: =IF(F39="","",E39-F39)
A40: =Estimate!A114 -> 1220 | B40: Woodwork/Cabinets/Millwork | C40: Finish Carpentry | D40: =Estimate!K114 -> N | E40: =Estimate!F114 -> 0 | G40: =IF(F40="","",E40-F40)
...

Sheet Schedule
A1: PROJECT SCHEDULE (one line per estimate item — add the items below as each job needs them)
A3: ID | B3: Task | C3: Dur | D3: Start | E3: Finish | F3: Pred | G3: Anchor | H3: Status | I3: % Done
A4: 1 | B4: 0110 Permits | C4: =IFERROR(NETWORKDAYS(D4,E4),"") | D4: =IF(COUNT(D5:D6)=0,"",MIN(D5:D6)) | E4: =IF(COUNT(E5:E6)=0,"",MAX(E5:E6)) | H4: =IF(I4>=1,"Complete",IF(I4>0,"In Progress","Not Started")) -> Not Started | I4: =IFERROR(SUMPRODUCT((B5:B6<>"")*I5:I6)/SUMPRODUCT((B5:B6<>"")*1),0) -> 0
D5: =IF(C5="","",Settings!$C$36) | E5: =IF(D5="","",WORKDAY(D5,MAX(C5,1)-1))
D6: =IF(C6="","",IF(G6<>"",G6,IF(ISNUMBER(E5),WORKDAY(E5,1),Settings!$C$36))) | E6: =IF(D6="","",WORKDAY(D6,MAX(C6,1)-1))
A7: 2 | B7: 0120 Electrical Utility Connections | C7: =IFERROR(NETWORKDAYS(D7,E7),"") | D7: =IF(COUNT(D8:D9)=0,"",MIN(D8:D9)) | E7: =IF(COUNT(E8:E9)=0,"",MAX(E8:E9)) | H7: =IF(I7>=1,"Complete",IF(I7>0,"In Progress","Not Started")) -> Not Started | I7: =IFERROR(SUMPRODUCT((B8:B9<>"")*I8:I9)/SUMPRODUCT((B8:B9<>"")*1),0) -> 0
D8: =IF(C8="","",IF(G8<>"",G8,IF(ISNUMBER(E6),WORKDAY(E6,1),Settings!$C$36))) | E8: =IF(D8="","",WORKDAY(D8,MAX(C8,1)-1))
D9: =IF(C9="","",IF(G9<>"",G9,IF(ISNUMBER(E8),WORKDAY(E8,1),Settings!$C$36))) | E9: =IF(D9="","",WORKDAY(D9,MAX(C9,1)-1))
A10: 3 | B10: 0130 Excavation | C10: =IFERROR(NETWORKDAYS(D10,E10),"") | D10: =IF(COUNT(D11:D12)=0,"",MIN(D11:D12)) | E10: =IF(COUNT(E11:E12)=0,"",MAX(E11:E12)) | H10: =IF(I10>=1,"Complete",IF(I10>0,"In Progress","Not Started")) -> Not Started | I10: =IFERROR(SUMPRODUCT((B11:B12<>"")*I11:I12)/SUMPRODUCT((B11:B12<>"")*1),0) -> 0
D11: =IF(C11="","",IF(G11<>"",G11,IF(ISNUMBER(E9),WORKDAY(E9,1),Settings!$C$36))) | E11: =IF(D11="","",WORKDAY(D11,MAX(C11,1)-1))
D12: =IF(C12="","",IF(G12<>"",G12,IF(ISNUMBER(E11),WORKDAY(E11,1),Settings!$C$36))) | E12: =IF(D12="","",WORKDAY(D12,MAX(C12,1)-1))
A13: 4 | B13: 0140 Septic system design & install | C13: =IFERROR(NETWORKDAYS(D13,E13),"") | D13: =IF(COUNT(D14:D15)=0,"",MIN(D14:D15)) | E13: =IF(COUNT(E14:E15)=0,"",MAX(E14:E15)) | H13: =IF(I13>=1,"Complete",IF(I13>0,"In Progress","Not Started")) -> Not Started | I13: =IFERROR(SUMPRODUCT((B14:B15<>"")*I14:I15)/SUMPRODUCT((B14:B15<>"")*1),0) -> 0
D14: =IF(C14="","",IF(G14<>"",G14,IF(ISNUMBER(E12),WORKDAY(E12,1),Settings!$C$36))) | E14: =IF(D14="","",WORKDAY(D14,MAX(C14,1)-1))
D15: =IF(C15="","",IF(G15<>"",G15,IF(ISNUMBER(E14),WORKDAY(E14,1),Settings!$C$36))) | E15: =IF(D15="","",WORKDAY(D15,MAX(C15,1)-1))
A16: 5 | B16: 0210 Footing And Foundation | C16: =IFERROR(NETWORKDAYS(D16,E16),"") | D16: =IF(COUNT(D17:D18)=0,"",MIN(D17:D18)) | E16: =IF(COUNT(E17:E18)=0,"",MAX(E17:E18)) | H16: =IF(I16>=1,"Complete",IF(I16>0,"In Progress","Not Started")) -> Not Started | I16: =IFERROR(SUMPRODUCT((B17:B18<>"")*I17:I18)/SUMPRODUCT((B17:B18<>"")*1),0) -> 0
D17: =IF(C17="","",IF(G17<>"",G17,IF(ISNUMBER(E15),WORKDAY(E15,1),Settings!$C$36))) | E17: =IF(D17="","",WORKDAY(D17,MAX(C17,1)-1))
D18: =IF(C18="","",IF(G18<>"",G18,IF(ISNUMBER(E17),WORKDAY(E17,1),Settings!$C$36))) | E18: =IF(D18="","",WORKDAY(D18,MAX(C18,1)-1))
A19: 6 | B19: 0310 Framing Materials | C19: =IFERROR(NETWORKDAYS(D19,E19),"") | D19: =IF(COUNT(D20:D21)=0,"",MIN(D20:D21)) | E19: =IF(COUNT(E20:E21)=0,"",MAX(E20:E21)) | H19: =IF(I19>=1,"Complete",IF(I19>0,"In Progress","Not Started")) -> Not Started | I19: =IFERROR(SUMPRODUCT((B20:B21<>"")*I20:I21)/SUMPRODUCT((B20:B21<>"")*1),0) -> 0
D20: =IF(C20="","",IF(G20<>"",G20,IF(ISNUMBER(E18),WORKDAY(E18,1),Settings!$C$36))) | E20: =IF(D20="","",WORKDAY(D20,MAX(C20,1)-1))
D21: =IF(C21="","",IF(G21<>"",G21,IF(ISNUMBER(E20),WORKDAY(E20,1),Settings!$C$36))) | E21: =IF(D21="","",WORKDAY(D21,MAX(C21,1)-1))
A22: 7 | B22: 0320 Framing Labor | C22: =IFERROR(NETWORKDAYS(D22,E22),"") | D22: =IF(COUNT(D23:D24)=0,"",MIN(D23:D24)) | E22: =IF(COUNT(E23:E24)=0,"",MAX(E23:E24)) | H22: =IF(I22>=1,"Complete",IF(I22>0,"In Progress","Not Started")) -> Not Started | I22: =IFERROR(SUMPRODUCT((B23:B24<>"")*I23:I24)/SUMPRODUCT((B23:B24<>"")*1),0) -> 0
D23: =IF(C23="","",IF(G23<>"",G23,IF(ISNUMBER(E21),WORKDAY(E21,1),Settings!$C$36))) | E23: =IF(D23="","",WORKDAY(D23,MAX(C23,1)-1))
D24: =IF(C24="","",IF(G24<>"",G24,IF(ISNUMBER(E23),WORKDAY(E23,1),Settings!$C$36))) | E24: =IF(D24="","",WORKDAY(D24,MAX(C24,1)-1))
A25: 8 | B25: 0410 Front Door | C25: =IFERROR(NETWORKDAYS(D25,E25),"") | D25: =IF(COUNT(D26:D27)=0,"",MIN(D26:D27)) | E25: =IF(COUNT(E26:E27)=0,"",MAX(E26:E27)) | H25: =IF(I25>=1,"Complete",IF(I25>0,"In Progress","Not Started")) -> Not Started | I25: =IFERROR(SUMPRODUCT((B26:B27<>"")*I26:I27)/SUMPRODUCT((B26:B27<>"")*1),0) -> 0
D26: =IF(C26="","",IF(G26<>"",G26,IF(ISNUMBER(E24),WORKDAY(E24,1),Settings!$C$36))) | E26: =IF(D26="","",WORKDAY(D26,MAX(C26,1)-1))
D27: =IF(C27="","",IF(G27<>"",G27,IF(ISNUMBER(E26),WORKDAY(E26,1),Settings!$C$36))) | E27: =IF(D27="","",WORKDAY(D27,MAX(C27,1)-1))
A28: 9 | B28: 0420 Other exterior doors | C28: =IFERROR(NETWORKDAYS(D28,E28),"") | D28: =IF(COUNT(D29:D30)=0,"",MIN(D29:D30)) | E28: =IF(COUNT(E29:E30)=0,"",MAX(E29:E30)) | H28: =IF(I28>=1,"Complete",IF(I28>0,"In Progress","Not Started")) -> Not Started | I28: =IFERROR(SUMPRODUCT((B29:B30<>"")*I29:I30)/SUMPRODUCT((B29:B30<>"")*1),0) -> 0
D29: =IF(C29="","",IF(G29<>"",G29,IF(ISNUMBER(E27),WORKDAY(E27,1),Settings!$C$36))) | E29: =IF(D29="","",WORKDAY(D29,MAX(C29,1)-1))
D30: =IF(C30="","",IF(G30<>"",G30,IF(ISNUMBER(E29),WORKDAY(E29,1),Settings!$C$36))) | E30: =IF(D30="","",WORKDAY(D30,MAX(C30,1)-1))
A31: 10 | B31: 0430 Garage Doors | C31: =IFERROR(NETWORKDAYS(D31,E31),"") | D31: =IF(COUNT(D32:D33)=0,"",MIN(D32:D33)) | E31: =IF(COUNT(E32:E33)=0,"",MAX(E32:E33)) | H31: =IF(I31>=1,"Complete",IF(I31>0,"In Progress","Not Started")) -> Not Started | I31: =IFERROR(SUMPRODUCT((B32:B33<>"")*I32:I33)/SUMPRODUCT((B32:B33<>"")*1),0) -> 0
D32: =IF(C32="","",IF(G32<>"",G32,IF(ISNUMBER(E30),WORKDAY(E30,1),Settings!$C$36))) | E32: =IF(D32="","",WORKDAY(D32,MAX(C32,1)-1))
D33: =IF(C33="","",IF(G33<>"",G33,IF(ISNUMBER(E32),WORKDAY(E32,1),Settings!$C$36))) | E33: =IF(D33="","",WORKDAY(D33,MAX(C33,1)-1))
A34: 11 | B34: 0440 Windows | C34: =IFERROR(NETWORKDAYS(D34,E34),"") | D34: =IF(COUNT(D35:D36)=0,"",MIN(D35:D36)) | E34: =IF(COUNT(E35:E36)=0,"",MAX(E35:E36)) | H34: =IF(I34>=1,"Complete",IF(I34>0,"In Progress","Not Started")) -> Not Started | I34: =IFERROR(SUMPRODUCT((B35:B36<>"")*I35:I36)/SUMPRODUCT((B35:B36<>"")*1),0) -> 0
D35: =IF(C35="","",IF(G35<>"",G35,IF(ISNUMBER(E33),WORKDAY(E33,1),Settings!$C$36))) | E35: =IF(D35="","",WORKDAY(D35,MAX(C35,1)-1))
D36: =IF(C36="","",IF(G36<>"",G36,IF(ISNUMBER(E35),WORKDAY(E35,1),Settings!$C$36))) | E36: =IF(D36="","",WORKDAY(D36,MAX(C36,1)-1))
A37: 12 | B37: 0510 Siding Materials | C37: =IFERROR(NETWORKDAYS(D37,E37),"") | D37: =IF(COUNT(D38:D39)=0,"",MIN(D38:D39)) | E37: =IF(COUNT(E38:E39)=0,"",MAX(E38:E39)) | H37: =IF(I37>=1,"Complete",IF(I37>0,"In Progress","Not Started")) -> Not Started | I37: =IFERROR(SUMPRODUCT((B38:B39<>"")*I38:I39)/SUMPRODUCT((B38:B39<>"")*1),0) -> 0
D38: =IF(C38="","",IF(G38<>"",G38,IF(ISNUMBER(E36),WORKDAY(E36,1),Settings!$C$36))) | E38: =IF(D38="","",WORKDAY(D38,MAX(C38,1)-1))
D39: =IF(C39="","",IF(G39<>"",G39,IF(ISNUMBER(E38),WORKDAY(E38,1),Settings!$C$36))) | E39: =IF(D39="","",WORKDAY(D39,MAX(C39,1)-1))
A40: 13 | B40: 0520 Siding Labor | C40: =IFERROR(NETWORKDAYS(D40,E40),"") | D40: =IF(COUNT(D41:D42)=0,"",MIN(D41:D42)) | E40: =IF(COUNT(E41:E42)=0,"",MAX(E41:E42)) | H40: =IF(I40>=1,"Complete",IF(I40>0,"In Progress","Not Started")) -> Not Started | I40: =IFERROR(SUMPRODUCT((B41:B42<>"")*I41:I42)/SUMPRODUCT((B41:B42<>"")*1),0) -> 0
D41: =IF(C41="","",IF(G41<>"",G41,IF(ISNUMBER(E39),WORKDAY(E39,1),Settings!$C$36))) | E41: =IF(D41="","",WORKDAY(D41,MAX(C41,1)-1))
...

Sheet Calendar
A1: PROJECT CALENDAR (auto from the Schedule — shaded = work happening; label = task starting that day)
A3: Week of | B3: Mon | C3: Tue | D3: Wed | E3: Thu | F3: Fri | G3: Sat | H3: Sun
A4: =(Settings!$C$36-(WEEKDAY(Settings!$C$36,2)-1))+0 -> 46202 | B4: =$A4+0 -> 46202 | C4: =$A4+1 -> 46203 | D4: =$A4+2 -> 46204 | E4: =$A4+3 -> 46205 | F4: =$A4+4 -> 46206 | G4: =$A4+5 -> 46207 | H4: =$A4+6 -> 46208
B5: =IFERROR(INDEX(Schedule!$B$4:$B$200,MATCH(B4,Schedule!$D$4:$D$200,0))&IF(COUNTIF(Schedule!$D$4:$D$200,B4)>1," +"&(COUNTIF(Schedule!$D$4:$D$200,B4)-1)&" more",""),"") | C5: =IFERROR(INDEX(Schedule!$B$4:$B$200,MATCH(C4,Schedule!$D$4:$D$200,0))&IF(COUNTIF(Schedule!$D$4:$D$200,C4)>1," +"&(COUNTIF(Schedule!$D$4:$D$200,C4)-1)&" more",""),"") | D5: =IFERROR(INDEX(Schedule!$B$4:$B$200,MATCH(D4,Schedule!$D$4:$D$200,0))&IF(COUNTIF(Schedule!$D$4:$D$200,D4)>1," +"&(COUNTIF(Schedule!$D$4:$D$200,D4)-1)&" more",""),"") | E5: =IFERROR(INDEX(Schedule!$B$4:$B$200,MATCH(E4,Schedule!$D$4:$D$200,0))&IF(COUNTIF(Schedule!$D$4:$D$200,E4)>1," +"&(COUNTIF(Schedule!$D$4:$D$200,E4)-1)&" more",""),"") | F5: =IFERROR(INDEX(Schedule!$B$4:$B$200,MATCH(F4,Schedule!$D$4:$D$200,0))&IF(COUNTIF(Schedule!$D$4:$D$200,F4)>1," +"&(COUNTIF(Schedule!$D$4:$D$200,F4)-1)&" more",""),"") | G5: =IFERROR(INDEX(Schedule!$B$4:$B$200,MATCH(G4,Schedule!$D$4:$D$200,0))&IF(COUNTIF(Schedule!$D$4:$D$200,G4)>1," +"&(COUNTIF(Schedule!$D$4:$D$200,G4)-1)&" more",""),"") | H5: =IFERROR(INDEX(Schedule!$B$4:$B$200,MATCH(H4,Schedule!$D$4:$D$200,0))&IF(COUNTIF(Schedule!$D$4:$D$200,H4)>1," +"&(COUNTIF(Schedule!$D$4:$D$200,H4)-1)&" more",""),"")
A6: =(Settings!$C$36-(WEEKDAY(Settings!$C$36,2)-1))+7 -> 46209 | B6: =$A6+0 -> 46209 | C6: =$A6+1 -> 46210 | D6: =$A6+2 -> 46211 | E6: =$A6+3 -> 46212 | F6: =$A6+4 -> 46213 | G6: =$A6+5 -> 46214 | H6: =$A6+6 -> 46215
B7: =IFERROR(INDEX(Schedule!$B$4:$B$200,MATCH(B6,Schedule!$D$4:$D$200,0))&IF(COUNTIF(Schedule!$D$4:$D$200,B6)>1," +"&(COUNTIF(Schedule!$D$4:$D$200,B6)-1)&" more",""),"") | C7: =IFERROR(INDEX(Schedule!$B$4:$B$200,MATCH(C6,Schedule!$D$4:$D$200,0))&IF(COUNTIF(Schedule!$D$4:$D$200,C6)>1," +"&(COUNTIF(Schedule!$D$4:$D$200,C6)-1)&" more",""),"") | D7: =IFERROR(INDEX(Schedule!$B$4:$B$200,MATCH(D6,Schedule!$D$4:$D$200,0))&IF(COUNTIF(Schedule!$D$4:$D$200,D6)>1," +"&(COUNTIF(Schedule!$D$4:$D$200,D6)-1)&" more",""),"") | E7: =IFERROR(INDEX(Schedule!$B$4:$B$200,MATCH(E6,Schedule!$D$4:$D$200,0))&IF(COUNTIF(Schedule!$D$4:$D$200,E6)>1," +"&(COUNTIF(Schedule!$D$4:$D$200,E6)-1)&" more",""),"") | F7: =IFERROR(INDEX(Schedule!$B$4:$B$200,MATCH(F6,Schedule!$D$4:$D$200,0))&IF(COUNTIF(Schedule!$D$4:$D$200,F6)>1," +"&(COUNTIF(Schedule!$D$4:$D$200,F6)-1)&" more",""),"") | G7: =IFERROR(INDEX(Schedule!$B$4:$B$200,MATCH(G6,Schedule!$D$4:$D$200,0))&IF(COUNTIF(Schedule!$D$4:$D$200,G6)>1," +"&(COUNTIF(Schedule!$D$4:$D$200,G6)-1)&" more",""),"") | H7: =IFERROR(INDEX(Schedule!$B$4:$B$200,MATCH(H6,Schedule!$D$4:$D$200,0))&IF(COUNTIF(Schedule!$D$4:$D$200,H6)>1," +"&(COUNTIF(Schedule!$D$4:$D$200,H6)-1)&" more",""),"")
A8: =(Settings!$C$36-(WEEKDAY(Settings!$C$36,2)-1))+14 -> 46216 | B8: =$A8+0 -> 46216 | C8: =$A8+1 -> 46217 | D8: =$A8+2 -> 46218 | E8: =$A8+3 -> 46219 | F8: =$A8+4 -> 46220 | G8: =$A8+5 -> 46221 | H8: =$A8+6 -> 46222
B9: =IFERROR(INDEX(Schedule!$B$4:$B$200,MATCH(B8,Schedule!$D$4:$D$200,0))&IF(COUNTIF(Schedule!$D$4:$D$200,B8)>1," +"&(COUNTIF(Schedule!$D$4:$D$200,B8)-1)&" more",""),"") | C9: =IFERROR(INDEX(Schedule!$B$4:$B$200,MATCH(C8,Schedule!$D$4:$D$200,0))&IF(COUNTIF(Schedule!$D$4:$D$200,C8)>1," +"&(COUNTIF(Schedule!$D$4:$D$200,C8)-1)&" more",""),"") | D9: =IFERROR(INDEX(Schedule!$B$4:$B$200,MATCH(D8,Schedule!$D$4:$D$200,0))&IF(COUNTIF(Schedule!$D$4:$D$200,D8)>1," +"&(COUNTIF(Schedule!$D$4:$D$200,D8)-1)&" more",""),"") | E9: =IFERROR(INDEX(Schedule!$B$4:$B$200,MATCH(E8,Schedule!$D$4:$D$200,0))&IF(COUNTIF(Schedule!$D$4:$D$200,E8)>1," +"&(COUNTIF(Schedule!$D$4:$D$200,E8)-1)&" more",""),"") | F9: =IFERROR(INDEX(Schedule!$B$4:$B$200,MATCH(F8,Schedule!$D$4:$D$200,0))&IF(COUNTIF(Schedule!$D$4:$D$200,F8)>1," +"&(COUNTIF(Schedule!$D$4:$D$200,F8)-1)&" more",""),"") | G9: =IFERROR(INDEX(Schedule!$B$4:$B$200,MATCH(G8,Schedule!$D$4:$D$200,0))&IF(COUNTIF(Schedule!$D$4:$D$200,G8)>1," +"&(COUNTIF(Schedule!$D$4:$D$200,G8)-1)&" more",""),"") | H9: =IFERROR(INDEX(Schedule!$B$4:$B$200,MATCH(H8,Schedule!$D$4:$D$200,0))&IF(COUNTIF(Schedule!$D$4:$D$200,H8)>1," +"&(COUNTIF(Schedule!$D$4:$D$200,H8)-1)&" more",""),"")
A10: =(Settings!$C$36-(WEEKDAY(Settings!$C$36,2)-1))+21 -> 46223 | B10: =$A10+0 -> 46223 | C10: =$A10+1 -> 46224 | D10: =$A10+2 -> 46225 | E10: =$A10+3 -> 46226 | F10: =$A10+4 -> 46227 | G10: =$A10+5 -> 46228 | H10: =$A10+6 -> 46229
B11: =IFERROR(INDEX(Schedule!$B$4:$B$200,MATCH(B10,Schedule!$D$4:$D$200,0))&IF(COUNTIF(Schedule!$D$4:$D$200,B10)>1," +"&(COUNTIF(Schedule!$D$4:$D$200,B10)-1)&" more",""),"") | C11: =IFERROR(INDEX(Schedule!$B$4:$B$200,MATCH(C10,Schedule!$D$4:$D$200,0))&IF(COUNTIF(Schedule!$D$4:$D$200,C10)>1," +"&(COUNTIF(Schedule!$D$4:$D$200,C10)-1)&" more",""),"") | D11: =IFERROR(INDEX(Schedule!$B$4:$B$200,MATCH(D10,Schedule!$D$4:$D$200,0))&IF(COUNTIF(Schedule!$D$4:$D$200,D10)>1," +"&(COUNTIF(Schedule!$D$4:$D$200,D10)-1)&" more",""),"") | E11: =IFERROR(INDEX(Schedule!$B$4:$B$200,MATCH(E10,Schedule!$D$4:$D$200,0))&IF(COUNTIF(Schedule!$D$4:$D$200,E10)>1," +"&(COUNTIF(Schedule!$D$4:$D$200,E10)-1)&" more",""),"") | F11: =IFERROR(INDEX(Schedule!$B$4:$B$200,MATCH(F10,Schedule!$D$4:$D$200,0))&IF(COUNTIF(Schedule!$D$4:$D$200,F10)>1," +"&(COUNTIF(Schedule!$D$4:$D$200,F10)-1)&" more",""),"") | G11: =IFERROR(INDEX(Schedule!$B$4:$B$200,MATCH(G10,Schedule!$D$4:$D$200,0))&IF(COUNTIF(Schedule!$D$4:$D$200,G10)>1," +"&(COUNTIF(Schedule!$D$4:$D$200,G10)-1)&" more",""),"") | H11: =IFERROR(INDEX(Schedule!$B$4:$B$200,MATCH(H10,Schedule!$D$4:$D$200,0))&IF(COUNTIF(Schedule!$D$4:$D$200,H10)>1," +"&(COUNTIF(Schedule!$D$4:$D$200,H10)-1)&" more",""),"")
A12: =(Settings!$C$36-(WEEKDAY(Settings!$C$36,2)-1))+28 -> 46230 | B12: =$A12+0 -> 46230 | C12: =$A12+1 -> 46231 | D12: =$A12+2 -> 46232 | E12: =$A12+3 -> 46233 | F12: =$A12+4 -> 46234 | G12: =$A12+5 -> 46235 | H12: =$A12+6 -> 46236
B13: =IFERROR(INDEX(Schedule!$B$4:$B$200,MATCH(B12,Schedule!$D$4:$D$200,0))&IF(COUNTIF(Schedule!$D$4:$D$200,B12)>1," +"&(COUNTIF(Schedule!$D$4:$D$200,B12)-1)&" more",""),"") | C13: =IFERROR(INDEX(Schedule!$B$4:$B$200,MATCH(C12,Schedule!$D$4:$D$200,0))&IF(COUNTIF(Schedule!$D$4:$D$200,C12)>1," +"&(COUNTIF(Schedule!$D$4:$D$200,C12)-1)&" more",""),"") | D13: =IFERROR(INDEX(Schedule!$B$4:$B$200,MATCH(D12,Schedule!$D$4:$D$200,0))&IF(COUNTIF(Schedule!$D$4:$D$200,D12)>1," +"&(COUNTIF(Schedule!$D$4:$D$200,D12)-1)&" more",""),"") | E13: =IFERROR(INDEX(Schedule!$B$4:$B$200,MATCH(E12,Schedule!$D$4:$D$200,0))&IF(COUNTIF(Schedule!$D$4:$D$200,E12)>1," +"&(COUNTIF(Schedule!$D$4:$D$200,E12)-1)&" more",""),"") | F13: =IFERROR(INDEX(Schedule!$B$4:$B$200,MATCH(F12,Schedule!$D$4:$D$200,0))&IF(COUNTIF(Schedule!$D$4:$D$200,F12)>1," +"&(COUNTIF(Schedule!$D$4:$D$200,F12)-1)&" more",""),"") | G13: =IFERROR(INDEX(Schedule!$B$4:$B$200,MATCH(G12,Schedule!$D$4:$D$200,0))&IF(COUNTIF(Schedule!$D$4:$D$200,G12)>1," +"&(COUNTIF(Schedule!$D$4:$D$200,G12)-1)&" more",""),"") | H13: =IFERROR(INDEX(Schedule!$B$4:$B$200,MATCH(H12,Schedule!$D$4:$D$200,0))&IF(COUNTIF(Schedule!$D$4:$D$200,H12)>1," +"&(COUNTIF(Schedule!$D$4:$D$200,H12)-1)&" more",""),"")
A14: =(Settings!$C$36-(WEEKDAY(Settings!$C$36,2)-1))+35 -> 46237 | B14: =$A14+0 -> 46237 | C14: =$A14+1 -> 46238 | D14: =$A14+2 -> 46239 | E14: =$A14+3 -> 46240 | F14: =$A14+4 -> 46241 | G14: =$A14+5 -> 46242 | H14: =$A14+6 -> 46243
B15: =IFERROR(INDEX(Schedule!$B$4:$B$200,MATCH(B14,Schedule!$D$4:$D$200,0))&IF(COUNTIF(Schedule!$D$4:$D$200,B14)>1," +"&(COUNTIF(Schedule!$D$4:$D$200,B14)-1)&" more",""),"") | C15: =IFERROR(INDEX(Schedule!$B$4:$B$200,MATCH(C14,Schedule!$D$4:$D$200,0))&IF(COUNTIF(Schedule!$D$4:$D$200,C14)>1," +"&(COUNTIF(Schedule!$D$4:$D$200,C14)-1)&" more",""),"") | D15: =IFERROR(INDEX(Schedule!$B$4:$B$200,MATCH(D14,Schedule!$D$4:$D$200,0))&IF(COUNTIF(Schedule!$D$4:$D$200,D14)>1," +"&(COUNTIF(Schedule!$D$4:$D$200,D14)-1)&" more",""),"") | E15: =IFERROR(INDEX(Schedule!$B$4:$B$200,MATCH(E14,Schedule!$D$4:$D$200,0))&IF(COUNTIF(Schedule!$D$4:$D$200,E14)>1," +"&(COUNTIF(Schedule!$D$4:$D$200,E14)-1)&" more",""),"") | F15: =IFERROR(INDEX(Schedule!$B$4:$B$200,MATCH(F14,Schedule!$D$4:$D$200,0))&IF(COUNTIF(Schedule!$D$4:$D$200,F14)>1," +"&(COUNTIF(Schedule!$D$4:$D$200,F14)-1)&" more",""),"") | G15: =IFERROR(INDEX(Schedule!$B$4:$B$200,MATCH(G14,Schedule!$D$4:$D$200,0))&IF(COUNTIF(Schedule!$D$4:$D$200,G14)>1," +"&(COUNTIF(Schedule!$D$4:$D$200,G14)-1)&" more",""),"") | H15: =IFERROR(INDEX(Schedule!$B$4:$B$200,MATCH(H14,Schedule!$D$4:$D$200,0))&IF(COUNTIF(Schedule!$D$4:$D$200,H14)>1," +"&(COUNTIF(Schedule!$D$4:$D$200,H14)-1)&" more",""),"")
A16: =(Settings!$C$36-(WEEKDAY(Settings!$C$36,2)-1))+42 -> 46244 | B16: =$A16+0 -> 46244 | C16: =$A16+1 -> 46245 | D16: =$A16+2 -> 46246 | E16: =$A16+3 -> 46247 | F16: =$A16+4 -> 46248 | G16: =$A16+5 -> 46249 | H16: =$A16+6 -> 46250
B17: =IFERROR(INDEX(Schedule!$B$4:$B$200,MATCH(B16,Schedule!$D$4:$D$200,0))&IF(COUNTIF(Schedule!$D$4:$D$200,B16)>1," +"&(COUNTIF(Schedule!$D$4:$D$200,B16)-1)&" more",""),"") | C17: =IFERROR(INDEX(Schedule!$B$4:$B$200,MATCH(C16,Schedule!$D$4:$D$200,0))&IF(COUNTIF(Schedule!$D$4:$D$200,C16)>1," +"&(COUNTIF(Schedule!$D$4:$D$200,C16)-1)&" more",""),"") | D17: =IFERROR(INDEX(Schedule!$B$4:$B$200,MATCH(D16,Schedule!$D$4:$D$200,0))&IF(COUNTIF(Schedule!$D$4:$D$200,D16)>1," +"&(COUNTIF(Schedule!$D$4:$D$200,D16)-1)&" more",""),"") | E17: =IFERROR(INDEX(Schedule!$B$4:$B$200,MATCH(E16,Schedule!$D$4:$D$200,0))&IF(COUNTIF(Schedule!$D$4:$D$200,E16)>1," +"&(COUNTIF(Schedule!$D$4:$D$200,E16)-1)&" more",""),"") | F17: =IFERROR(INDEX(Schedule!$B$4:$B$200,MATCH(F16,Schedule!$D$4:$D$200,0))&IF(COUNTIF(Schedule!$D$4:$D$200,F16)>1," +"&(COUNTIF(Schedule!$D$4:$D$200,F16)-1)&" more",""),"") | G17: =IFERROR(INDEX(Schedule!$B$4:$B$200,MATCH(G16,Schedule!$D$4:$D$200,0))&IF(COUNTIF(Schedule!$D$4:$D$200,G16)>1," +"&(COUNTIF(Schedule!$D$4:$D$200,G16)-1)&" more",""),"") | H17: =IFERROR(INDEX(Schedule!$B$4:$B$200,MATCH(H16,Schedule!$D$4:$D$200,0))&IF(COUNTIF(Schedule!$D$4:$D$200,H16)>1," +"&(COUNTIF(Schedule!$D$4:$D$200,H16)-1)&" more",""),"")
A18: =(Settings!$C$36-(WEEKDAY(Settings!$C$36,2)-1))+49 -> 46251 | B18: =$A18+0 -> 46251 | C18: =$A18+1 -> 46252 | D18: =$A18+2 -> 46253 | E18: =$A18+3 -> 46254 | F18: =$A18+4 -> 46255 | G18: =$A18+5 -> 46256 | H18: =$A18+6 -> 46257
B19: =IFERROR(INDEX(Schedule!$B$4:$B$200,MATCH(B18,Schedule!$D$4:$D$200,0))&IF(COUNTIF(Schedule!$D$4:$D$200,B18)>1," +"&(COUNTIF(Schedule!$D$4:$D$200,B18)-1)&" more",""),"") | C19: =IFERROR(INDEX(Schedule!$B$4:$B$200,MATCH(C18,Schedule!$D$4:$D$200,0))&IF(COUNTIF(Schedule!$D$4:$D$200,C18)>1," +"&(COUNTIF(Schedule!$D$4:$D$200,C18)-1)&" more",""),"") | D19: =IFERROR(INDEX(Schedule!$B$4:$B$200,MATCH(D18,Schedule!$D$4:$D$200,0))&IF(COUNTIF(Schedule!$D$4:$D$200,D18)>1," +"&(COUNTIF(Schedule!$D$4:$D$200,D18)-1)&" more",""),"") | E19: =IFERROR(INDEX(Schedule!$B$4:$B$200,MATCH(E18,Schedule!$D$4:$D$200,0))&IF(COUNTIF(Schedule!$D$4:$D$200,E18)>1," +"&(COUNTIF(Schedule!$D$4:$D$200,E18)-1)&" more",""),"") | F19: =IFERROR(INDEX(Schedule!$B$4:$B$200,MATCH(F18,Schedule!$D$4:$D$200,0))&IF(COUNTIF(Schedule!$D$4:$D$200,F18)>1," +"&(COUNTIF(Schedule!$D$4:$D$200,F18)-1)&" more",""),"") | G19: =IFERROR(INDEX(Schedule!$B$4:$B$200,MATCH(G18,Schedule!$D$4:$D$200,0))&IF(COUNTIF(Schedule!$D$4:$D$200,G18)>1," +"&(COUNTIF(Schedule!$D$4:$D$200,G18)-1)&" more",""),"") | H19: =IFERROR(INDEX(Schedule!$B$4:$B$200,MATCH(H18,Schedule!$D$4:$D$200,0))&IF(COUNTIF(Schedule!$D$4:$D$200,H18)>1," +"&(COUNTIF(Schedule!$D$4:$D$200,H18)-1)&" more",""),"")
A20: =(Settings!$C$36-(WEEKDAY(Settings!$C$36,2)-1))+56 -> 46258 | B20: =$A20+0 -> 46258 | C20: =$A20+1 -> 46259 | D20: =$A20+2 -> 46260 | E20: =$A20+3 -> 46261 | F20: =$A20+4 -> 46262 | G20: =$A20+5 -> 46263 | H20: =$A20+6 -> 46264
B21: =IFERROR(INDEX(Schedule!$B$4:$B$200,MATCH(B20,Schedule!$D$4:$D$200,0))&IF(COUNTIF(Schedule!$D$4:$D$200,B20)>1," +"&(COUNTIF(Schedule!$D$4:$D$200,B20)-1)&" more",""),"") | C21: =IFERROR(INDEX(Schedule!$B$4:$B$200,MATCH(C20,Schedule!$D$4:$D$200,0))&IF(COUNTIF(Schedule!$D$4:$D$200,C20)>1," +"&(COUNTIF(Schedule!$D$4:$D$200,C20)-1)&" more",""),"") | D21: =IFERROR(INDEX(Schedule!$B$4:$B$200,MATCH(D20,Schedule!$D$4:$D$200,0))&IF(COUNTIF(Schedule!$D$4:$D$200,D20)>1," +"&(COUNTIF(Schedule!$D$4:$D$200,D20)-1)&" more",""),"") | E21: =IFERROR(INDEX(Schedule!$B$4:$B$200,MATCH(E20,Schedule!$D$4:$D$200,0))&IF(COUNTIF(Schedule!$D$4:$D$200,E20)>1," +"&(COUNTIF(Schedule!$D$4:$D$200,E20)-1)&" more",""),"") | F21: =IFERROR(INDEX(Schedule!$B$4:$B$200,MATCH(F20,Schedule!$D$4:$D$200,0))&IF(COUNTIF(Schedule!$D$4:$D$200,F20)>1," +"&(COUNTIF(Schedule!$D$4:$D$200,F20)-1)&" more",""),"") | G21: =IFERROR(INDEX(Schedule!$B$4:$B$200,MATCH(G20,Schedule!$D$4:$D$200,0))&IF(COUNTIF(Schedule!$D$4:$D$200,G20)>1," +"&(COUNTIF(Schedule!$D$4:$D$200,G20)-1)&" more",""),"") | H21: =IFERROR(INDEX(Schedule!$B$4:$B$200,MATCH(H20,Schedule!$D$4:$D$200,0))&IF(COUNTIF(Schedule!$D$4:$D$200,H20)>1," +"&(COUNTIF(Schedule!$D$4:$D$200,H20)-1)&" more",""),"")
A22: =(Settings!$C$36-(WEEKDAY(Settings!$C$36,2)-1))+63 -> 46265 | B22: =$A22+0 -> 46265 | C22: =$A22+1 -> 46266 | D22: =$A22+2 -> 46267 | E22: =$A22+3 -> 46268 | F22: =$A22+4 -> 46269 | G22: =$A22+5 -> 46270 | H22: =$A22+6 -> 46271
B23: =IFERROR(INDEX(Schedule!$B$4:$B$200,MATCH(B22,Schedule!$D$4:$D$200,0))&IF(COUNTIF(Schedule!$D$4:$D$200,B22)>1," +"&(COUNTIF(Schedule!$D$4:$D$200,B22)-1)&" more",""),"") | C23: =IFERROR(INDEX(Schedule!$B$4:$B$200,MATCH(C22,Schedule!$D$4:$D$200,0))&IF(COUNTIF(Schedule!$D$4:$D$200,C22)>1," +"&(COUNTIF(Schedule!$D$4:$D$200,C22)-1)&" more",""),"") | D23: =IFERROR(INDEX(Schedule!$B$4:$B$200,MATCH(D22,Schedule!$D$4:$D$200,0))&IF(COUNTIF(Schedule!$D$4:$D$200,D22)>1," +"&(COUNTIF(Schedule!$D$4:$D$200,D22)-1)&" more",""),"") | E23: =IFERROR(INDEX(Schedule!$B$4:$B$200,MATCH(E22,Schedule!$D$4:$D$200,0))&IF(COUNTIF(Schedule!$D$4:$D$200,E22)>1," +"&(COUNTIF(Schedule!$D$4:$D$200,E22)-1)&" more",""),"") | F23: =IFERROR(INDEX(Schedule!$B$4:$B$200,MATCH(F22,Schedule!$D$4:$D$200,0))&IF(COUNTIF(Schedule!$D$4:$D$200,F22)>1," +"&(COUNTIF(Schedule!$D$4:$D$200,F22)-1)&" more",""),"") | G23: =IFERROR(INDEX(Schedule!$B$4:$B$200,MATCH(G22,Schedule!$D$4:$D$200,0))&IF(COUNTIF(Schedule!$D$4:$D$200,G22)>1," +"&(COUNTIF(Schedule!$D$4:$D$200,G22)-1)&" more",""),"") | H23: =IFERROR(INDEX(Schedule!$B$4:$B$200,MATCH(H22,Schedule!$D$4:$D$200,0))&IF(COUNTIF(Schedule!$D$4:$D$200,H22)>1," +"&(COUNTIF(Schedule!$D$4:$D$200,H22)-1)&" more",""),"")
A24: =(Settings!$C$36-(WEEKDAY(Settings!$C$36,2)-1))+70 -> 46272 | B24: =$A24+0 -> 46272 | C24: =$A24+1 -> 46273 | D24: =$A24+2 -> 46274 | E24: =$A24+3 -> 46275 | F24: =$A24+4 -> 46276 | G24: =$A24+5 -> 46277 | H24: =$A24+6 -> 46278
B25: =IFERROR(INDEX(Schedule!$B$4:$B$200,MATCH(B24,Schedule!$D$4:$D$200,0))&IF(COUNTIF(Schedule!$D$4:$D$200,B24)>1," +"&(COUNTIF(Schedule!$D$4:$D$200,B24)-1)&" more",""),"") | C25: =IFERROR(INDEX(Schedule!$B$4:$B$200,MATCH(C24,Schedule!$D$4:$D$200,0))&IF(COUNTIF(Schedule!$D$4:$D$200,C24)>1," +"&(COUNTIF(Schedule!$D$4:$D$200,C24)-1)&" more",""),"") | D25: =IFERROR(INDEX(Schedule!$B$4:$B$200,MATCH(D24,Schedule!$D$4:$D$200,0))&IF(COUNTIF(Schedule!$D$4:$D$200,D24)>1," +"&(COUNTIF(Schedule!$D$4:$D$200,D24)-1)&" more",""),"") | E25: =IFERROR(INDEX(Schedule!$B$4:$B$200,MATCH(E24,Schedule!$D$4:$D$200,0))&IF(COUNTIF(Schedule!$D$4:$D$200,E24)>1," +"&(COUNTIF(Schedule!$D$4:$D$200,E24)-1)&" more",""),"") | F25: =IFERROR(INDEX(Schedule!$B$4:$B$200,MATCH(F24,Schedule!$D$4:$D$200,0))&IF(COUNTIF(Schedule!$D$4:$D$200,F24)>1," +"&(COUNTIF(Schedule!$D$4:$D$200,F24)-1)&" more",""),"") | G25: =IFERROR(INDEX(Schedule!$B$4:$B$200,MATCH(G24,Schedule!$D$4:$D$200,0))&IF(COUNTIF(Schedule!$D$4:$D$200,G24)>1," +"&(COUNTIF(Schedule!$D$4:$D$200,G24)-1)&" more",""),"") | H25: =IFERROR(INDEX(Schedule!$B$4:$B$200,MATCH(H24,Schedule!$D$4:$D$200,0))&IF(COUNTIF(Schedule!$D$4:$D$200,H24)>1," +"&(COUNTIF(Schedule!$D$4:$D$200,H24)-1)&" more",""),"")
A26: =(Settings!$C$36-(WEEKDAY(Settings!$C$36,2)-1))+77 -> 46279 | B26: =$A26+0 -> 46279 | C26: =$A26+1 -> 46280 | D26: =$A26+2 -> 46281 | E26: =$A26+3 -> 46282 | F26: =$A26+4 -> 46283 | G26: =$A26+5 -> 46284 | H26: =$A26+6 -> 46285
B27: =IFERROR(INDEX(Schedule!$B$4:$B$200,MATCH(B26,Schedule!$D$4:$D$200,0))&IF(COUNTIF(Schedule!$D$4:$D$200,B26)>1," +"&(COUNTIF(Schedule!$D$4:$D$200,B26)-1)&" more",""),"") | C27: =IFERROR(INDEX(Schedule!$B$4:$B$200,MATCH(C26,Schedule!$D$4:$D$200,0))&IF(COUNTIF(Schedule!$D$4:$D$200,C26)>1," +"&(COUNTIF(Schedule!$D$4:$D$200,C26)-1)&" more",""),"") | D27: =IFERROR(INDEX(Schedule!$B$4:$B$200,MATCH(D26,Schedule!$D$4:$D$200,0))&IF(COUNTIF(Schedule!$D$4:$D$200,D26)>1," +"&(COUNTIF(Schedule!$D$4:$D$200,D26)-1)&" more",""),"") | E27: =IFERROR(INDEX(Schedule!$B$4:$B$200,MATCH(E26,Schedule!$D$4:$D$200,0))&IF(COUNTIF(Schedule!$D$4:$D$200,E26)>1," +"&(COUNTIF(Schedule!$D$4:$D$200,E26)-1)&" more",""),"") | F27: =IFERROR(INDEX(Schedule!$B$4:$B$200,MATCH(F26,Schedule!$D$4:$D$200,0))&IF(COUNTIF(Schedule!$D$4:$D$200,F26)>1," +"&(COUNTIF(Schedule!$D$4:$D$200,F26)-1)&" more",""),"") | G27: =IFERROR(INDEX(Schedule!$B$4:$B$200,MATCH(G26,Schedule!$D$4:$D$200,0))&IF(COUNTIF(Schedule!$D$4:$D$200,G26)>1," +"&(COUNTIF(Schedule!$D$4:$D$200,G26)-1)&" more",""),"") | H27: =IFERROR(INDEX(Schedule!$B$4:$B$200,MATCH(H26,Schedule!$D$4:$D$200,0))&IF(COUNTIF(Schedule!$D$4:$D$200,H26)>1," +"&(COUNTIF(Schedule!$D$4:$D$200,H26)-1)&" more",""),"")
A28: =(Settings!$C$36-(WEEKDAY(Settings!$C$36,2)-1))+84 -> 46286 | B28: =$A28+0 -> 46286 | C28: =$A28+1 -> 46287 | D28: =$A28+2 -> 46288 | E28: =$A28+3 -> 46289 | F28: =$A28+4 -> 46290 | G28: =$A28+5 -> 46291 | H28: =$A28+6 -> 46292
B29: =IFERROR(INDEX(Schedule!$B$4:$B$200,MATCH(B28,Schedule!$D$4:$D$200,0))&IF(COUNTIF(Schedule!$D$4:$D$200,B28)>1," +"&(COUNTIF(Schedule!$D$4:$D$200,B28)-1)&" more",""),"") | C29: =IFERROR(INDEX(Schedule!$B$4:$B$200,MATCH(C28,Schedule!$D$4:$D$200,0))&IF(COUNTIF(Schedule!$D$4:$D$200,C28)>1," +"&(COUNTIF(Schedule!$D$4:$D$200,C28)-1)&" more",""),"") | D29: =IFERROR(INDEX(Schedule!$B$4:$B$200,MATCH(D28,Schedule!$D$4:$D$200,0))&IF(COUNTIF(Schedule!$D$4:$D$200,D28)>1," +"&(COUNTIF(Schedule!$D$4:$D$200,D28)-1)&" more",""),"") | E29: =IFERROR(INDEX(Schedule!$B$4:$B$200,MATCH(E28,Schedule!$D$4:$D$200,0))&IF(COUNTIF(Schedule!$D$4:$D$200,E28)>1," +"&(COUNTIF(Schedule!$D$4:$D$200,E28)-1)&" more",""),"") | F29: =IFERROR(INDEX(Schedule!$B$4:$B$200,MATCH(F28,Schedule!$D$4:$D$200,0))&IF(COUNTIF(Schedule!$D$4:$D$200,F28)>1," +"&(COUNTIF(Schedule!$D$4:$D$200,F28)-1)&" more",""),"") | G29: =IFERROR(INDEX(Schedule!$B$4:$B$200,MATCH(G28,Schedule!$D$4:$D$200,0))&IF(COUNTIF(Schedule!$D$4:$D$200,G28)>1," +"&(COUNTIF(Schedule!$D$4:$D$200,G28)-1)&" more",""),"") | H29: =IFERROR(INDEX(Schedule!$B$4:$B$200,MATCH(H28,Schedule!$D$4:$D$200,0))&IF(COUNTIF(Schedule!$D$4:$D$200,H28)>1," +"&(COUNTIF(Schedule!$D$4:$D$200,H28)-1)&" more",""),"")
A30: =(Settings!$C$36-(WEEKDAY(Settings!$C$36,2)-1))+91 -> 46293 | B30: =$A30+0 -> 46293 | C30: =$A30+1 -> 46294 | D30: =$A30+2 -> 46295 | E30: =$A30+3 -> 46296 | F30: =$A30+4 -> 46297 | G30: =$A30+5 -> 46298 | H30: =$A30+6 -> 46299
B31: =IFERROR(INDEX(Schedule!$B$4:$B$200,MATCH(B30,Schedule!$D$4:$D$200,0))&IF(COUNTIF(Schedule!$D$4:$D$200,B30)>1," +"&(COUNTIF(Schedule!$D$4:$D$200,B30)-1)&" more",""),"") | C31: =IFERROR(INDEX(Schedule!$B$4:$B$200,MATCH(C30,Schedule!$D$4:$D$200,0))&IF(COUNTIF(Schedule!$D$4:$D$200,C30)>1," +"&(COUNTIF(Schedule!$D$4:$D$200,C30)-1)&" more",""),"") | D31: =IFERROR(INDEX(Schedule!$B$4:$B$200,MATCH(D30,Schedule!$D$4:$D$200,0))&IF(COUNTIF(Schedule!$D$4:$D$200,D30)>1," +"&(COUNTIF(Schedule!$D$4:$D$200,D30)-1)&" more",""),"") | E31: =IFERROR(INDEX(Schedule!$B$4:$B$200,MATCH(E30,Schedule!$D$4:$D$200,0))&IF(COUNTIF(Schedule!$D$4:$D$200,E30)>1," +"&(COUNTIF(Schedule!$D$4:$D$200,E30)-1)&" more",""),"") | F31: =IFERROR(INDEX(Schedule!$B$4:$B$200,MATCH(F30,Schedule!$D$4:$D$200,0))&IF(COUNTIF(Schedule!$D$4:$D$200,F30)>1," +"&(COUNTIF(Schedule!$D$4:$D$200,F30)-1)&" more",""),"") | G31: =IFERROR(INDEX(Schedule!$B$4:$B$200,MATCH(G30,Schedule!$D$4:$D$200,0))&IF(COUNTIF(Schedule!$D$4:$D$200,G30)>1," +"&(COUNTIF(Schedule!$D$4:$D$200,G30)-1)&" more",""),"") | H31: =IFERROR(INDEX(Schedule!$B$4:$B$200,MATCH(H30,Schedule!$D$4:$D$200,0))&IF(COUNTIF(Schedule!$D$4:$D$200,H30)>1," +"&(COUNTIF(Schedule!$D$4:$D$200,H30)-1)&" more",""),"")
A32: =(Settings!$C$36-(WEEKDAY(Settings!$C$36,2)-1))+98 -> 46300 | B32: =$A32+0 -> 46300 | C32: =$A32+1 -> 46301 | D32: =$A32+2 -> 46302 | E32: =$A32+3 -> 46303 | F32: =$A32+4 -> 46304 | G32: =$A32+5 -> 46305 | H32: =$A32+6 -> 46306
B33: =IFERROR(INDEX(Schedule!$B$4:$B$200,MATCH(B32,Schedule!$D$4:$D$200,0))&IF(COUNTIF(Schedule!$D$4:$D$200,B32)>1," +"&(COUNTIF(Schedule!$D$4:$D$200,B32)-1)&" more",""),"") | C33: =IFERROR(INDEX(Schedule!$B$4:$B$200,MATCH(C32,Schedule!$D$4:$D$200,0))&IF(COUNTIF(Schedule!$D$4:$D$200,C32)>1," +"&(COUNTIF(Schedule!$D$4:$D$200,C32)-1)&" more",""),"") | D33: =IFERROR(INDEX(Schedule!$B$4:$B$200,MATCH(D32,Schedule!$D$4:$D$200,0))&IF(COUNTIF(Schedule!$D$4:$D$200,D32)>1," +"&(COUNTIF(Schedule!$D$4:$D$200,D32)-1)&" more",""),"") | E33: =IFERROR(INDEX(Schedule!$B$4:$B$200,MATCH(E32,Schedule!$D$4:$D$200,0))&IF(COUNTIF(Schedule!$D$4:$D$200,E32)>1," +"&(COUNTIF(Schedule!$D$4:$D$200,E32)-1)&" more",""),"") | F33: =IFERROR(INDEX(Schedule!$B$4:$B$200,MATCH(F32,Schedule!$D$4:$D$200,0))&IF(COUNTIF(Schedule!$D$4:$D$200,F32)>1," +"&(COUNTIF(Schedule!$D$4:$D$200,F32)-1)&" more",""),"") | G33: =IFERROR(INDEX(Schedule!$B$4:$B$200,MATCH(G32,Schedule!$D$4:$D$200,0))&IF(COUNTIF(Schedule!$D$4:$D$200,G32)>1," +"&(COUNTIF(Schedule!$D$4:$D$200,G32)-1)&" more",""),"") | H33: =IFERROR(INDEX(Schedule!$B$4:$B$200,MATCH(H32,Schedule!$D$4:$D$200,0))&IF(COUNTIF(Schedule!$D$4:$D$200,H32)>1," +"&(COUNTIF(Schedule!$D$4:$D$200,H32)-1)&" more",""),"")
A34: =(Settings!$C$36-(WEEKDAY(Settings!$C$36,2)-1))+105 -> 46307 | B34: =$A34+0 -> 46307 | C34: =$A34+1 -> 46308 | D34: =$A34+2 -> 46309 | E34: =$A34+3 -> 46310 | F34: =$A34+4 -> 46311 | G34: =$A34+5 -> 46312 | H34: =$A34+6 -> 46313
B35: =IFERROR(INDEX(Schedule!$B$4:$B$200,MATCH(B34,Schedule!$D$4:$D$200,0))&IF(COUNTIF(Schedule!$D$4:$D$200,B34)>1," +"&(COUNTIF(Schedule!$D$4:$D$200,B34)-1)&" more",""),"") | C35: =IFERROR(INDEX(Schedule!$B$4:$B$200,MATCH(C34,Schedule!$D$4:$D$200,0))&IF(COUNTIF(Schedule!$D$4:$D$200,C34)>1," +"&(COUNTIF(Schedule!$D$4:$D$200,C34)-1)&" more",""),"") | D35: =IFERROR(INDEX(Schedule!$B$4:$B$200,MATCH(D34,Schedule!$D$4:$D$200,0))&IF(COUNTIF(Schedule!$D$4:$D$200,D34)>1," +"&(COUNTIF(Schedule!$D$4:$D$200,D34)-1)&" more",""),"") | E35: =IFERROR(INDEX(Schedule!$B$4:$B$200,MATCH(E34,Schedule!$D$4:$D$200,0))&IF(COUNTIF(Schedule!$D$4:$D$200,E34)>1," +"&(COUNTIF(Schedule!$D$4:$D$200,E34)-1)&" more",""),"") | F35: =IFERROR(INDEX(Schedule!$B$4:$B$200,MATCH(F34,Schedule!$D$4:$D$200,0))&IF(COUNTIF(Schedule!$D$4:$D$200,F34)>1," +"&(COUNTIF(Schedule!$D$4:$D$200,F34)-1)&" more",""),"") | G35: =IFERROR(INDEX(Schedule!$B$4:$B$200,MATCH(G34,Schedule!$D$4:$D$200,0))&IF(COUNTIF(Schedule!$D$4:$D$200,G34)>1," +"&(COUNTIF(Schedule!$D$4:$D$200,G34)-1)&" more",""),"") | H35: =IFERROR(INDEX(Schedule!$B$4:$B$200,MATCH(H34,Schedule!$D$4:$D$200,0))&IF(COUNTIF(Schedule!$D$4:$D$200,H34)>1," +"&(COUNTIF(Schedule!$D$4:$D$200,H34)-1)&" more",""),"")
A36: =(Settings!$C$36-(WEEKDAY(Settings!$C$36,2)-1))+112 -> 46314 | B36: =$A36+0 -> 46314 | C36: =$A36+1 -> 46315 | D36: =$A36+2 -> 46316 | E36: =$A36+3 -> 46317 | F36: =$A36+4 -> 46318 | G36: =$A36+5 -> 46319 | H36: =$A36+6 -> 46320
B37: =IFERROR(INDEX(Schedule!$B$4:$B$200,MATCH(B36,Schedule!$D$4:$D$200,0))&IF(COUNTIF(Schedule!$D$4:$D$200,B36)>1," +"&(COUNTIF(Schedule!$D$4:$D$200,B36)-1)&" more",""),"") | C37: =IFERROR(INDEX(Schedule!$B$4:$B$200,MATCH(C36,Schedule!$D$4:$D$200,0))&IF(COUNTIF(Schedule!$D$4:$D$200,C36)>1," +"&(COUNTIF(Schedule!$D$4:$D$200,C36)-1)&" more",""),"") | D37: =IFERROR(INDEX(Schedule!$B$4:$B$200,MATCH(D36,Schedule!$D$4:$D$200,0))&IF(COUNTIF(Schedule!$D$4:$D$200,D36)>1," +"&(COUNTIF(Schedule!$D$4:$D$200,D36)-1)&" more",""),"") | E37: =IFERROR(INDEX(Schedule!$B$4:$B$200,MATCH(E36,Schedule!$D$4:$D$200,0))&IF(COUNTIF(Schedule!$D$4:$D$200,E36)>1," +"&(COUNTIF(Schedule!$D$4:$D$200,E36)-1)&" more",""),"") | F37: =IFERROR(INDEX(Schedule!$B$4:$B$200,MATCH(F36,Schedule!$D$4:$D$200,0))&IF(COUNTIF(Schedule!$D$4:$D$200,F36)>1," +"&(COUNTIF(Schedule!$D$4:$D$200,F36)-1)&" more",""),"") | G37: =IFERROR(INDEX(Schedule!$B$4:$B$200,MATCH(G36,Schedule!$D$4:$D$200,0))&IF(COUNTIF(Schedule!$D$4:$D$200,G36)>1," +"&(COUNTIF(Schedule!$D$4:$D$200,G36)-1)&" more",""),"") | H37: =IFERROR(INDEX(Schedule!$B$4:$B$200,MATCH(H36,Schedule!$D$4:$D$200,0))&IF(COUNTIF(Schedule!$D$4:$D$200,H36)>1," +"&(COUNTIF(Schedule!$D$4:$D$200,H36)-1)&" more",""),"")
A38: =(Settings!$C$36-(WEEKDAY(Settings!$C$36,2)-1))+119 -> 46321 | B38: =$A38+0 -> 46321 | C38: =$A38+1 -> 46322 | D38: =$A38+2 -> 46323 | E38: =$A38+3 -> 46324 | F38: =$A38+4 -> 46325 | G38: =$A38+5 -> 46326 | H38: =$A38+6 -> 46327
B39: =IFERROR(INDEX(Schedule!$B$4:$B$200,MATCH(B38,Schedule!$D$4:$D$200,0))&IF(COUNTIF(Schedule!$D$4:$D$200,B38)>1," +"&(COUNTIF(Schedule!$D$4:$D$200,B38)-1)&" more",""),"") | C39: =IFERROR(INDEX(Schedule!$B$4:$B$200,MATCH(C38,Schedule!$D$4:$D$200,0))&IF(COUNTIF(Schedule!$D$4:$D$200,C38)>1," +"&(COUNTIF(Schedule!$D$4:$D$200,C38)-1)&" more",""),"") | D39: =IFERROR(INDEX(Schedule!$B$4:$B$200,MATCH(D38,Schedule!$D$4:$D$200,0))&IF(COUNTIF(Schedule!$D$4:$D$200,D38)>1," +"&(COUNTIF(Schedule!$D$4:$D$200,D38)-1)&" more",""),"") | E39: =IFERROR(INDEX(Schedule!$B$4:$B$200,MATCH(E38,Schedule!$D$4:$D$200,0))&IF(COUNTIF(Schedule!$D$4:$D$200,E38)>1," +"&(COUNTIF(Schedule!$D$4:$D$200,E38)-1)&" more",""),"") | F39: =IFERROR(INDEX(Schedule!$B$4:$B$200,MATCH(F38,Schedule!$D$4:$D$200,0))&IF(COUNTIF(Schedule!$D$4:$D$200,F38)>1," +"&(COUNTIF(Schedule!$D$4:$D$200,F38)-1)&" more",""),"") | G39: =IFERROR(INDEX(Schedule!$B$4:$B$200,MATCH(G38,Schedule!$D$4:$D$200,0))&IF(COUNTIF(Schedule!$D$4:$D$200,G38)>1," +"&(COUNTIF(Schedule!$D$4:$D$200,G38)-1)&" more",""),"") | H39: =IFERROR(INDEX(Schedule!$B$4:$B$200,MATCH(H38,Schedule!$D$4:$D$200,0))&IF(COUNTIF(Schedule!$D$4:$D$200,H38)>1," +"&(COUNTIF(Schedule!$D$4:$D$200,H38)-1)&" more",""),"")
A40: =(Settings!$C$36-(WEEKDAY(Settings!$C$36,2)-1))+126 -> 46328 | B40: =$A40+0 -> 46328 | C40: =$A40+1 -> 46329 | D40: =$A40+2 -> 46330 | E40: =$A40+3 -> 46331 | F40: =$A40+4 -> 46332 | G40: =$A40+5 -> 46333 | H40: =$A40+6 -> 46334
B41: =IFERROR(INDEX(Schedule!$B$4:$B$200,MATCH(B40,Schedule!$D$4:$D$200,0))&IF(COUNTIF(Schedule!$D$4:$D$200,B40)>1," +"&(COUNTIF(Schedule!$D$4:$D$200,B40)-1)&" more",""),"") | C41: =IFERROR(INDEX(Schedule!$B$4:$B$200,MATCH(C40,Schedule!$D$4:$D$200,0))&IF(COUNTIF(Schedule!$D$4:$D$200,C40)>1," +"&(COUNTIF(Schedule!$D$4:$D$200,C40)-1)&" more",""),"") | D41: =IFERROR(INDEX(Schedule!$B$4:$B$200,MATCH(D40,Schedule!$D$4:$D$200,0))&IF(COUNTIF(Schedule!$D$4:$D$200,D40)>1," +"&(COUNTIF(Schedule!$D$4:$D$200,D40)-1)&" more",""),"") | E41: =IFERROR(INDEX(Schedule!$B$4:$B$200,MATCH(E40,Schedule!$D$4:$D$200,0))&IF(COUNTIF(Schedule!$D$4:$D$200,E40)>1," +"&(COUNTIF(Schedule!$D$4:$D$200,E40)-1)&" more",""),"") | F41: =IFERROR(INDEX(Schedule!$B$4:$B$200,MATCH(F40,Schedule!$D$4:$D$200,0))&IF(COUNTIF(Schedule!$D$4:$D$200,F40)>1," +"&(COUNTIF(Schedule!$D$4:$D$200,F40)-1)&" more",""),"") | G41: =IFERROR(INDEX(Schedule!$B$4:$B$200,MATCH(G40,Schedule!$D$4:$D$200,0))&IF(COUNTIF(Schedule!$D$4:$D$200,G40)>1," +"&(COUNTIF(Schedule!$D$4:$D$200,G40)-1)&" more",""),"") | H41: =IFERROR(INDEX(Schedule!$B$4:$B$200,MATCH(H40,Schedule!$D$4:$D$200,0))&IF(COUNTIF(Schedule!$D$4:$D$200,H40)>1," +"&(COUNTIF(Schedule!$D$4:$D$200,H40)-1)&" more",""),"")
...

Sheet Exclusions
D1: EXCLUSIONS
D2: =Settings!C40&" • "&Settings!C41 -> PO Box 516, Longview, WA 98632 • 360-200-1716
D3: ="Project: "&Settings!C8&" Estimate "&Settings!C10 -> Project: Truesdell SFD Estimate EST-1001
A4: Lines toggled Excl? = Y on the Estimate are excluded (cost zeroed) and collected here for reference.
A5: Item | B5: Excluded line | C5: Value | D5: Excl?
A6: Permits | B6: =Estimate!B8 -> Bldg. Permit | C6: =Estimate!H8 -> 0 | D6: =Estimate!L8 -> N
A7: Electrical Utility Connections | B7: =Estimate!B10 -> PUD Quoted install | C7: =Estimate!H10 -> 0 | D7: =Estimate!L10 -> N
A8: Electrical Utility Connections | B8: =Estimate!B11 -> Gas service connection | C8: =Estimate!H11 -> 0 | D8: =Estimate!L11 -> N
A9: Excavation | B9: =Estimate!B13 -> Excavation | C9: =Estimate!H13 -> 0 | D9: =Estimate!L13 -> N
A10: Excavation | B10: =Estimate!B14 -> Excavation - utilities & contingency | C10: =Estimate!H14 -> 0 | D10: =Estimate!L14 -> N
A11: Excavation | B11: =Estimate!B15 -> Backfill - Labor | C11: =Estimate!H15 -> 0 | D11: =Estimate!L15 -> N
A12: Excavation | B12: =Estimate!B16 -> Backfill - Gravel and fill | C12: =Estimate!H16 -> 0 | D12: =Estimate!L16 -> N
